Detector: mtcnn. Recognizer: DeepFace.
Imagem S035_1933_1969_F_A.jpg e S035_1933_1970_F_A.jpg
Exception:Graph execution error:

Detected at node 'model_2/L4/Reshape_279' defined at (most recent call last):
    File "/usr/lib/python3.8/threading.py", line 890, in _bootstrap
      self._bootstrap_inner()
    File "/usr/lib/python3.8/threading.py", line 932, in _bootstrap_inner
      self.run()
    File "/usr/lib/python3.8/threading.py", line 870, in run
      self._target(*self._args, **self._kwargs)
    File "Thread_Test_2-CPU-2.py", line 76, in recognition_thread
      result = DeepFace.verify(img1_path = img1_path, img2_path = img2_path, model_name=recognizer, distance_metric = "cosine", detector_backend = models_detection[3])
    File "/home/fvbcarneiro/.local/lib/python3.8/site-packages/deepface/DeepFace.py", line 163, in verify
      img1_representation = represent(img_path = img1_path
    File "/home/fvbcarneiro/.local/lib/python3.8/site-packages/deepface/DeepFace.py", line 768, in represent
      embedding = model.predict(img)[0].tolist()
    File "/home/fvbcarneiro/.local/lib/python3.8/site-packages/keras/utils/traceback_utils.py", line 65, in error_handler
      return fn(*args, **kwargs)
    File "/home/fvbcarneiro/.local/lib/python3.8/site-packages/keras/engine/training.py", line 2350, in predict
      tmp_batch_outputs = self.predict_function(iterator)
    File "/home/fvbcarneiro/.local/lib/python3.8/site-packages/keras/engine/training.py", line 2137, in predict_function
      return step_function(self, iterator)
    File "/home/fvbcarneiro/.local/lib/python3.8/site-packages/keras/engine/training.py", line 2123, in step_function
      outputs = model.distribute_strategy.run(run_step, args=(data,))
    File "/home/fvbcarneiro/.local/lib/python3.8/site-packages/keras/engine/training.py", line 2111, in run_step
      outputs = model.predict_step(data)
    File "/home/fvbcarneiro/.local/lib/python3.8/site-packages/keras/engine/training.py", line 2079, in predict_step
      return self(x, training=False)
    File "/home/fvbcarneiro/.local/lib/python3.8/site-packages/keras/utils/traceback_utils.py", line 65, in error_handler
      return fn(*args, **kwargs)
    File "/home/fvbcarneiro/.local/lib/python3.8/site-packages/keras/engine/training.py", line 561, in __call__
      return super().__call__(*args, **kwargs)
    File "/home/fvbcarneiro/.local/lib/python3.8/site-packages/keras/utils/traceback_utils.py", line 65, in error_handler
      return fn(*args, **kwargs)
    File "/home/fvbcarneiro/.local/lib/python3.8/site-packages/keras/engine/base_layer.py", line 1132, in __call__
      outputs = call_fn(inputs, *args, **kwargs)
    File "/home/fvbcarneiro/.local/lib/python3.8/site-packages/keras/utils/traceback_utils.py", line 96, in error_handler
      return fn(*args, **kwargs)
    File "/home/fvbcarneiro/.local/lib/python3.8/site-packages/keras/engine/functional.py", line 511, in call
      return self._run_internal_graph(inputs, training=training, mask=mask)
    File "/home/fvbcarneiro/.local/lib/python3.8/site-packages/keras/engine/functional.py", line 668, in _run_internal_graph
      outputs = node.layer(*args, **kwargs)
    File "/home/fvbcarneiro/.local/lib/python3.8/site-packages/keras/utils/traceback_utils.py", line 65, in error_handler
      return fn(*args, **kwargs)
    File "/home/fvbcarneiro/.local/lib/python3.8/site-packages/keras/engine/base_layer.py", line 1132, in __call__
      outputs = call_fn(inputs, *args, **kwargs)
    File "/home/fvbcarneiro/.local/lib/python3.8/site-packages/keras/utils/traceback_utils.py", line 96, in error_handler
      return fn(*args, **kwargs)
    File "/home/fvbcarneiro/.local/lib/python3.8/site-packages/keras/layers/locally_connected/locally_connected2d.py", line 336, in call
      output = backend.local_conv(
    File "/home/fvbcarneiro/.local/lib/python3.8/site-packages/keras/backend.py", line 6634, in local_conv
      xs.append(reshape(inputs[slices], (1, -1, feature_dim)))
    File "/home/fvbcarneiro/.local/lib/python3.8/site-packages/keras/backend.py", line 3603, in reshape
      return tf.reshape(x, shape)
Node: 'model_2/L4/Reshape_279'
Input to reshape is a tensor with 1008 values, but the requested shape requires a multiple of 1296
	 [[{{node model_2/L4/Reshape_279}}]] [Op:__inference_predict_function_369343]

Detector: mtcnn. Recognizer: DeepID.
Imagem S035_1933_1970_F_A.jpg e S035_1933_1971_F_A.jpg
Exception:Face could not be detected. Please confirm that the picture is a face photo or consider to set enforce_detection param to False.

Detector: mtcnn. Recognizer: OpenFace.
Imagem S035_1933_1993_F_A.jpg e S035_1933_1994_F_A.jpg
Exception:Face could not be detected. Please confirm that the picture is a face photo or consider to set enforce_detection param to False.

Detector: mtcnn. Recognizer: DeepID.
Imagem S035_1933_1996_F_A.jpg e S035_1933_1997_F_A.jpg
Exception:Face could not be detected. Please confirm that the picture is a face photo or consider to set enforce_detection param to False.

Detector: mtcnn. Recognizer: DeepFace.
Imagem S035_1933_2008_F_A.jpg e S035_1933_2009_F_A.jpg
Exception:Face could not be detected. Please confirm that the picture is a face photo or consider to set enforce_detection param to False.

